<?xml version="1.0" ?>
<!-- =================================================================================== -->
<!-- |    This document was autogenerated by xacro from robot.xacro                    | -->
<!-- |    EDITING THIS FILE BY HAND IS NOT RECOMMENDED                                 | -->
<!-- =================================================================================== -->
<mujoco model="go1">
  <compiler angle="radian" eulerseq="XYZ" meshdir="../meshes/simplified_stl"/>
  <size nconmax="100" njmax="500"/>
  <option gravity="0 0 -9.806" iterations="50" noslip_iterations="50" solver="Newton" timestep="0.0005"/>
  <default>
    <geom solimp="0.9 0.95 0.001 0.5 2.0" solref="0.002 1.0"/>
    <light castshadow="false" diffuse="1 1 1"/>
    <camera fovy="60"/>
    <default class="visual">
      <geom conaffinity="0" contype="0" group="2" material="silver"/>
    </default>
    <default class="collision">
      <!-- condim=3 means no torsional or rolling fric, so last 2 friction attributes set 0 -->
      <geom conaffinity="1" condim="3" contype="1" friction="0.6 0.0 0.0" group="3" material="blue"/>
    </default>
    <default class="collision_all">
      <!-- condim=3 means no torsional or rolling fric, so last 2 friction attributes set 0 -->
      <geom conaffinity="15" condim="3" contype="15" friction="0.6 0.0 0.0" group="0"/>
    </default>
  </default>
  <asset>
    <material name="black" rgba="0.0 0.0 0.0 1.0"/>
    <material name="blue" rgba="0.0 0.0 0.8 1.0"/>
    <material name="green" rgba="0.0 0.8 0.0 1.0"/>
    <material name="silver" rgba="0.9137254901960784 0.9137254901960784 0.8470588235294118 1.0"/>
    <material name="red" rgba="0.8 0.0 0.0 1.0"/>
    <texture builtin="gradient" height="512" rgb1="0.4 0.6 0.8" rgb2="0 0 0" type="skybox" width="512"/>
    <texture builtin="checker" height="300" mark="edge" markrgb="0.8 0.8 0.8" name="plane" rgb1="0.2 0.3 0.4" rgb2="0.1 0.2 0.3" type="2d" width="300"/>
    <material name="plane" reflectance="0.2" texrepeat="5 5" texture="plane" texuniform="true"/>
    <mesh file="trunk.stl" name="trunk"/>
    <mesh file="hip.stl" name="hip"/>
    <mesh file="thigh.stl" name="thigh"/>
    <mesh file="thigh_mirror.stl" name="thigh_mirror"/>
    <mesh file="calf.stl" name="calf"/>
  </asset>
  <visual>
    <headlight ambient="0.1 0.1 0.1" diffuse="0.6 0.6 0.6" specular="0.9 0.9 0.9"/>
    <rgba haze="0.15 0.25 0.35 1"/>
  </visual>
  <worldbody>
    <light diffuse=".8 .8 .8" dir="0 0 -10" directional="true" pos="0 0 10"/>
    <camera mode="trackcom" name="trackcom_RightHoriz" pos="0 -0.8 0.3" xyaxes="1 0 0 0 0 1"/>
    <camera mode="trackcom" name="tackcom_RightAbove10deg" pos="0 -0.9 0.5" xyaxes="1 0 0 0 0.174 0.985"/>
    <geom class="collision_all" material="plane" name="floor" pos="0 0 0" size="0 0 1" type="plane"/>
    <body name="trunk" pos="0 0 0.5">
      <inertial fullinertia="0.0168128557 0.063009565 0.0716547275 -0.0002296769 -0.0002945293 -4.18731e-05" mass="5.204" pos="0.0223 0.002 -0.0005"/>
      <freejoint/>
      <geom class="visual" mesh="trunk" type="mesh"/>
      <geom class="collision" size="0.125 0.04675 0.057" type="box"/>
      <geom class="collision" euler="0 1.5707963267948966 0" pos="0.27 0.0 0.005" size="0.07 0.025" type="cylinder"/>
      <site euler="0 0 0" name="trunk_cheat_site" pos="0 0 0"/>
      <site name="imu" pos="-0.01592 -0.06659 -0.00617"/>
      <body name="FR_hip" pos="0.1881 -0.04675 0">
        <inertial fullinertia="0.000334008405 0.000619101213 0.00040057614 1.0826066e-05 1.290732e-06 -1.643194e-06" mass="0.591" pos="-0.005657 0.008752 -0.000102"/>
        <joint actuatorfrcrange="-23.7 23.7" armature="0.02" axis="1 0 0" damping="0.0" frictionloss="0.0" name="FR_hip_joint" pos="0 0 0" range="-0.863 0.863" type="hinge"/>
        <geom class="visual" euler="3.141592653589793 0 0" mesh="hip" pos="0 0 0" type="mesh"/>
        <geom class="collision" euler="1.5707963267948966 0 0" pos="0 -0.08 0" size="0.046 0.02" type="cylinder"/>
        <body name="FR_thigh" pos="0 -0.08 0">
          <inertial fullinertia="0.004431760472 0.004485671726 0.000740309489 -5.7496807e-05 -0.000218457134 -0.000572001265" mass="0.92" pos="-0.003342 0.018054 -0.033451"/>
          <joint actuatorfrcrange="-23.7 23.7" armature="0.02" axis="0 1 0" damping="0.0" frictionloss="0.0" name="FR_thigh_joint" pos="0 0 0" range="-0.686 4.501" type="hinge"/>
          <geom class="visual" euler="0 0 0" mesh="thigh_mirror" pos="0 0 0" type="mesh"/>
          <geom class="collision" euler="0 1.5707963267948966 0" pos="0 0 -0.1065" size="0.1065 0.01225 0.017" type="box"/>
          <body name="FR_calf" pos="0 0 -0.213">
            <inertial fullinertia="0.001088793059 0.001100428748 2.4787446e-05 -2.55679e-07 7.117814e-06 2.077264e-06" mass="0.135862" pos="0.006197 0.001408 -0.116695"/>
            <joint actuatorfrcrange="-35.55 35.55" armature="0.02" axis="0 1 0" damping="0.0" frictionloss="0.0" name="FR_calf_joint" pos="0 0 0" range="-2.818 -0.888" type="hinge"/>
            <geom class="visual" euler="0 0 0" mesh="calf" pos="0 0 0" type="mesh"/>
            <geom class="collision" euler="0 1.5707963267948966 0" pos="0 0 -0.1065" size="0.1065 0.008 0.008" type="box"/>
            <body name="FR_foot" pos="0 0 -0.213">
              <inertial diaginertia="9.600000000000001e-06 9.600000000000001e-06 9.600000000000001e-06" mass="0.06" pos="0 0 0"/>
              <body name="FR_foot_for_collision" pos="0 0 0">
                <inertial diaginertia="1e-14 1e-14 1e-14" mass="1e-6" pos="0 0 0"/>
                <geom class="collision" euler="0 0 0" pos="0 0 0" size="0.02" type="sphere"/>
                <site name="FR_grf_sensor" pos="0 0 0" size="0.017" type="sphere"/>
              </body>
            </body>
          </body>
          <body name="FR_calf_rotor" pos="0.0 0.03235 0">
            <inertial fullinertia="5.9647e-05 0.000111842 5.9647e-05 0.0 0.0 0.0" mass="0.089" pos="0.0 0.0 0.0"/>
            <geom class="visual" euler="1.5707963267948966 0 0" material="green" pos="0 0 0" size="0.035 0.01" type="cylinder"/>
          </body>
        </body>
        <body name="FR_thigh_rotor" pos="0.0 0.00015 0">
          <inertial fullinertia="5.9647e-05 0.000111842 5.9647e-05 0.0 0.0 0.0" mass="0.089" pos="0.0 0.0 0.0"/>
          <geom class="visual" euler="1.5707963267948966 0 0" material="green" pos="0 0 0" size="0.035 0.01" type="cylinder"/>
        </body>
      </body>
      <body name="FR_hip_rotor" pos="0.11215 -0.04675 0">
        <inertial fullinertia="0.000111842 5.9647e-05 5.9647e-05 0.0 0.0 0.0" mass="0.089" pos="0.0 0.0 0.0"/>
        <geom class="visual" euler="0 1.5707963267948966 0" material="green" pos="0 0 0" size="0.035 0.01" type="cylinder"/>
      </body>
      <body name="FL_hip" pos="0.1881 0.04675 0">
        <inertial fullinertia="0.000334008405 0.000619101213 0.00040057614 -1.0826066e-05 1.290732e-06 1.643194e-06" mass="0.591" pos="-0.005657 -0.008752 -0.000102"/>
        <joint actuatorfrcrange="-23.7 23.7" armature="0.02" axis="1 0 0" damping="0.0" frictionloss="0.0" name="FL_hip_joint" pos="0 0 0" range="-0.863 0.863" type="hinge"/>
        <geom class="visual" euler="0 0 0" mesh="hip" pos="0 0 0" type="mesh"/>
        <geom class="collision" euler="1.5707963267948966 0 0" pos="0 0.08 0" size="0.046 0.02" type="cylinder"/>
        <body name="FL_thigh" pos="0 0.08 0">
          <inertial fullinertia="0.004431760472 0.004485671726 0.000740309489 5.7496807e-05 -0.000218457134 0.000572001265" mass="0.92" pos="-0.003342 -0.018054 -0.033451"/>
          <joint actuatorfrcrange="-23.7 23.7" armature="0.02" axis="0 1 0" damping="0.0" frictionloss="0.0" name="FL_thigh_joint" pos="0 0 0" range="-0.686 4.501" type="hinge"/>
          <geom class="visual" euler="0 0 0" mesh="thigh" pos="0 0 0" type="mesh"/>
          <geom class="collision" euler="0 1.5707963267948966 0" pos="0 0 -0.1065" size="0.1065 0.01225 0.017" type="box"/>
          <body name="FL_calf" pos="0 0 -0.213">
            <inertial fullinertia="0.001088793059 0.001100428748 2.4787446e-05 -2.55679e-07 7.117814e-06 2.077264e-06" mass="0.135862" pos="0.006197 0.001408 -0.116695"/>
            <joint actuatorfrcrange="-35.55 35.55" armature="0.02" axis="0 1 0" damping="0.0" frictionloss="0.0" name="FL_calf_joint" pos="0 0 0" range="-2.818 -0.888" type="hinge"/>
            <geom class="visual" euler="0 0 0" mesh="calf" pos="0 0 0" type="mesh"/>
            <geom class="collision" euler="0 1.5707963267948966 0" pos="0 0 -0.1065" size="0.1065 0.008 0.008" type="box"/>
            <body name="FL_foot" pos="0 0 -0.213">
              <inertial diaginertia="9.600000000000001e-06 9.600000000000001e-06 9.600000000000001e-06" mass="0.06" pos="0 0 0"/>
              <body name="FL_foot_for_collision" pos="0 0 0">
                <inertial diaginertia="1e-14 1e-14 1e-14" mass="1e-6" pos="0 0 0"/>
                <geom class="collision" euler="0 0 0" pos="0 0 0" size="0.02" type="sphere"/>
                <site name="FL_grf_sensor" pos="0 0 0" size="0.017" type="sphere"/>
              </body>
            </body>
          </body>
          <body name="FL_calf_rotor" pos="0.0 -0.03235 0">
            <inertial fullinertia="5.9647e-05 0.000111842 5.9647e-05 0.0 0.0 0.0" mass="0.089" pos="0.0 0.0 0.0"/>
            <geom class="visual" euler="1.5707963267948966 0 0" material="green" pos="0 0 0" size="0.035 0.01" type="cylinder"/>
          </body>
        </body>
        <body name="FL_thigh_rotor" pos="0.0 -0.00015 0">
          <inertial fullinertia="5.9647e-05 0.000111842 5.9647e-05 0.0 0.0 0.0" mass="0.089" pos="0.0 0.0 0.0"/>
          <geom class="visual" euler="1.5707963267948966 0 0" material="green" pos="0 0 0" size="0.035 0.01" type="cylinder"/>
        </body>
      </body>
      <body name="FL_hip_rotor" pos="0.11215 0.04675 0">
        <inertial fullinertia="0.000111842 5.9647e-05 5.9647e-05 0.0 0.0 0.0" mass="0.089" pos="0.0 0.0 0.0"/>
        <geom class="visual" euler="0 1.5707963267948966 0" material="green" pos="0 0 0" size="0.035 0.01" type="cylinder"/>
      </body>
      <body name="RR_hip" pos="-0.1881 -0.04675 0">
        <inertial fullinertia="0.000334008405 0.000619101213 0.00040057614 -1.0826066e-05 -1.290732e-06 -1.643194e-06" mass="0.591" pos="0.005657 0.008752 -0.000102"/>
        <joint actuatorfrcrange="-23.7 23.7" armature="0.02" axis="1 0 0" damping="0.0" frictionloss="0.0" name="RR_hip_joint" pos="0 0 0" range="-0.863 0.863" type="hinge"/>
        <geom class="visual" euler="3.141592653589793 3.141592653589793 0" mesh="hip" pos="0 0 0" type="mesh"/>
        <geom class="collision" euler="1.5707963267948966 0 0" pos="0 -0.08 0" size="0.046 0.02" type="cylinder"/>
        <body name="RR_thigh" pos="0 -0.08 0">
          <inertial fullinertia="0.004431760472 0.004485671726 0.000740309489 -5.7496807e-05 -0.000218457134 -0.000572001265" mass="0.92" pos="-0.003342 0.018054 -0.033451"/>
          <joint actuatorfrcrange="-23.7 23.7" armature="0.02" axis="0 1 0" damping="0.0" frictionloss="0.0" name="RR_thigh_joint" pos="0 0 0" range="-0.686 4.501" type="hinge"/>
          <geom class="visual" euler="0 0 0" mesh="thigh_mirror" pos="0 0 0" type="mesh"/>
          <geom class="collision" euler="0 1.5707963267948966 0" pos="0 0 -0.1065" size="0.1065 0.01225 0.017" type="box"/>
          <body name="RR_calf" pos="0 0 -0.213">
            <inertial fullinertia="0.001088793059 0.001100428748 2.4787446e-05 -2.55679e-07 7.117814e-06 2.077264e-06" mass="0.135862" pos="0.006197 0.001408 -0.116695"/>
            <joint actuatorfrcrange="-35.55 35.55" armature="0.02" axis="0 1 0" damping="0.0" frictionloss="0.0" name="RR_calf_joint" pos="0 0 0" range="-2.818 -0.888" type="hinge"/>
            <geom class="visual" euler="0 0 0" mesh="calf" pos="0 0 0" type="mesh"/>
            <geom class="collision" euler="0 1.5707963267948966 0" pos="0 0 -0.1065" size="0.1065 0.008 0.008" type="box"/>
            <body name="RR_foot" pos="0 0 -0.213">
              <inertial diaginertia="9.600000000000001e-06 9.600000000000001e-06 9.600000000000001e-06" mass="0.06" pos="0 0 0"/>
              <body name="RR_foot_for_collision" pos="0 0 0">
                <inertial diaginertia="1e-14 1e-14 1e-14" mass="1e-6" pos="0 0 0"/>
                <geom class="collision" euler="0 0 0" pos="0 0 0" size="0.02" type="sphere"/>
                <site name="RR_grf_sensor" pos="0 0 0" size="0.017" type="sphere"/>
              </body>
            </body>
          </body>
          <body name="RR_calf_rotor" pos="0.0 0.03235 0">
            <inertial fullinertia="5.9647e-05 0.000111842 5.9647e-05 0.0 0.0 0.0" mass="0.089" pos="0.0 0.0 0.0"/>
            <geom class="visual" euler="1.5707963267948966 0 0" material="green" pos="0 0 0" size="0.035 0.01" type="cylinder"/>
          </body>
        </body>
        <body name="RR_thigh_rotor" pos="0.0 0.00015 0">
          <inertial fullinertia="5.9647e-05 0.000111842 5.9647e-05 0.0 0.0 0.0" mass="0.089" pos="0.0 0.0 0.0"/>
          <geom class="visual" euler="1.5707963267948966 0 0" material="green" pos="0 0 0" size="0.035 0.01" type="cylinder"/>
        </body>
      </body>
      <body name="RR_hip_rotor" pos="-0.11215 -0.04675 0">
        <inertial fullinertia="0.000111842 5.9647e-05 5.9647e-05 0.0 0.0 0.0" mass="0.089" pos="0.0 0.0 0.0"/>
        <geom class="visual" euler="0 1.5707963267948966 0" material="green" pos="0 0 0" size="0.035 0.01" type="cylinder"/>
      </body>
      <body name="RL_hip" pos="-0.1881 0.04675 0">
        <inertial fullinertia="0.000334008405 0.000619101213 0.00040057614 1.0826066e-05 -1.290732e-06 1.643194e-06" mass="0.591" pos="0.005657 -0.008752 -0.000102"/>
        <joint actuatorfrcrange="-23.7 23.7" armature="0.02" axis="1 0 0" damping="0.0" frictionloss="0.0" name="RL_hip_joint" pos="0 0 0" range="-0.863 0.863" type="hinge"/>
        <geom class="visual" euler="0 3.141592653589793 0" mesh="hip" pos="0 0 0" type="mesh"/>
        <geom class="collision" euler="1.5707963267948966 0 0" pos="0 0.08 0" size="0.046 0.02" type="cylinder"/>
        <body name="RL_thigh" pos="0 0.08 0">
          <inertial fullinertia="0.004431760472 0.004485671726 0.000740309489 5.7496807e-05 -0.000218457134 0.000572001265" mass="0.92" pos="-0.003342 -0.018054 -0.033451"/>
          <joint actuatorfrcrange="-23.7 23.7" armature="0.02" axis="0 1 0" damping="0.0" frictionloss="0.0" name="RL_thigh_joint" pos="0 0 0" range="-0.686 4.501" type="hinge"/>
          <geom class="visual" euler="0 0 0" mesh="thigh" pos="0 0 0" type="mesh"/>
          <geom class="collision" euler="0 1.5707963267948966 0" pos="0 0 -0.1065" size="0.1065 0.01225 0.017" type="box"/>
          <body name="RL_calf" pos="0 0 -0.213">
            <inertial fullinertia="0.001088793059 0.001100428748 2.4787446e-05 -2.55679e-07 7.117814e-06 2.077264e-06" mass="0.135862" pos="0.006197 0.001408 -0.116695"/>
            <joint actuatorfrcrange="-35.55 35.55" armature="0.02" axis="0 1 0" damping="0.0" frictionloss="0.0" name="RL_calf_joint" pos="0 0 0" range="-2.818 -0.888" type="hinge"/>
            <geom class="visual" euler="0 0 0" mesh="calf" pos="0 0 0" type="mesh"/>
            <geom class="collision" euler="0 1.5707963267948966 0" pos="0 0 -0.1065" size="0.1065 0.008 0.008" type="box"/>
            <body name="RL_foot" pos="0 0 -0.213">
              <inertial diaginertia="9.600000000000001e-06 9.600000000000001e-06 9.600000000000001e-06" mass="0.06" pos="0 0 0"/>
              <body name="RL_foot_for_collision" pos="0 0 0">
                <inertial diaginertia="1e-14 1e-14 1e-14" mass="1e-6" pos="0 0 0"/>
                <geom class="collision" euler="0 0 0" pos="0 0 0" size="0.02" type="sphere"/>
                <site name="RL_grf_sensor" pos="0 0 0" size="0.017" type="sphere"/>
              </body>
            </body>
          </body>
          <body name="RL_calf_rotor" pos="0.0 -0.03235 0">
            <inertial fullinertia="5.9647e-05 0.000111842 5.9647e-05 0.0 0.0 0.0" mass="0.089" pos="0.0 0.0 0.0"/>
            <geom class="visual" euler="1.5707963267948966 0 0" material="green" pos="0 0 0" size="0.035 0.01" type="cylinder"/>
          </body>
        </body>
        <body name="RL_thigh_rotor" pos="0.0 -0.00015 0">
          <inertial fullinertia="5.9647e-05 0.000111842 5.9647e-05 0.0 0.0 0.0" mass="0.089" pos="0.0 0.0 0.0"/>
          <geom class="visual" euler="1.5707963267948966 0 0" material="green" pos="0 0 0" size="0.035 0.01" type="cylinder"/>
        </body>
      </body>
      <body name="RL_hip_rotor" pos="-0.11215 0.04675 0">
        <inertial fullinertia="0.000111842 5.9647e-05 5.9647e-05 0.0 0.0 0.0" mass="0.089" pos="0.0 0.0 0.0"/>
        <geom class="visual" euler="0 1.5707963267948966 0" material="green" pos="0 0 0" size="0.035 0.01" type="cylinder"/>
      </body>
    </body>
  </worldbody>
  <actuator>
    <motor gear="1" joint="FR_hip_joint" name="FR_hip"/>
    <motor gear="1" joint="FR_thigh_joint" name="FR_thigh"/>
    <motor gear="1" joint="FR_calf_joint" name="FR_calf"/>
    <motor gear="1" joint="FL_hip_joint" name="FL_hip"/>
    <motor gear="1" joint="FL_thigh_joint" name="FL_thigh"/>
    <motor gear="1" joint="FL_calf_joint" name="FL_calf"/>
    <motor gear="1" joint="RR_hip_joint" name="RR_hip"/>
    <motor gear="1" joint="RR_thigh_joint" name="RR_thigh"/>
    <motor gear="1" joint="RR_calf_joint" name="RR_calf"/>
    <motor gear="1" joint="RL_hip_joint" name="RL_hip"/>
    <motor gear="1" joint="RL_thigh_joint" name="RL_thigh"/>
    <motor gear="1" joint="RL_calf_joint" name="RL_calf"/>
  </actuator>
  <sensor>
    <jointpos joint="FR_hip_joint" name="FR_hip_pos"/>
    <jointpos joint="FR_thigh_joint" name="FR_thigh_pos"/>
    <jointpos joint="FR_calf_joint" name="FR_calf_pos"/>
    <jointpos joint="FL_hip_joint" name="FL_hip_pos"/>
    <jointpos joint="FL_thigh_joint" name="FL_thigh_pos"/>
    <jointpos joint="FL_calf_joint" name="FL_calf_pos"/>
    <jointpos joint="RR_hip_joint" name="RR_hip_pos"/>
    <jointpos joint="RR_thigh_joint" name="RR_thigh_pos"/>
    <jointpos joint="RR_calf_joint" name="RR_calf_pos"/>
    <jointpos joint="RL_hip_joint" name="RL_hip_pos"/>
    <jointpos joint="RL_thigh_joint" name="RL_thigh_pos"/>
    <jointpos joint="RL_calf_joint" name="RL_calf_pos"/>
    <jointvel joint="FR_hip_joint" name="FR_hip_vel"/>
    <jointvel joint="FR_thigh_joint" name="FR_thigh_vel"/>
    <jointvel joint="FR_calf_joint" name="FR_calf_vel"/>
    <jointvel joint="FL_hip_joint" name="FL_hip_vel"/>
    <jointvel joint="FL_thigh_joint" name="FL_thigh_vel"/>
    <jointvel joint="FL_calf_joint" name="FL_calf_vel"/>
    <jointvel joint="RR_hip_joint" name="RR_hip_vel"/>
    <jointvel joint="RR_thigh_joint" name="RR_thigh_vel"/>
    <jointvel joint="RR_calf_joint" name="RR_calf_vel"/>
    <jointvel joint="RL_hip_joint" name="RL_hip_vel"/>
    <jointvel joint="RL_thigh_joint" name="RL_thigh_vel"/>
    <jointvel joint="RL_calf_joint" name="RL_calf_vel"/>
    <actuatorfrc actuator="FR_hip" name="FR_hip_torque" noise="0.01"/>
    <actuatorfrc actuator="FR_thigh" name="FR_thigh_torque" noise="0.01"/>
    <actuatorfrc actuator="FR_calf" name="FR_calf_torque" noise="0.01"/>
    <actuatorfrc actuator="FL_hip" name="FL_hip_torque" noise="0.01"/>
    <actuatorfrc actuator="FL_thigh" name="FL_thigh_torque" noise="0.01"/>
    <actuatorfrc actuator="FL_calf" name="FL_calf_torque" noise="0.01"/>
    <actuatorfrc actuator="RR_hip" name="RR_hip_torque" noise="0.01"/>
    <actuatorfrc actuator="RR_thigh" name="RR_thigh_torque" noise="0.01"/>
    <actuatorfrc actuator="RR_calf" name="RR_calf_torque" noise="0.01"/>
    <actuatorfrc actuator="RL_hip" name="RL_hip_torque" noise="0.01"/>
    <actuatorfrc actuator="RL_thigh" name="RL_thigh_torque" noise="0.01"/>
    <actuatorfrc actuator="RL_calf" name="RL_calf_torque" noise="0.01"/>
    <framequat name="imu_quat" objname="imu" objtype="site"/>
    <gyro name="imu_gyro" noise="0.002" site="imu"/>
    <accelerometer name="imu_acc" noise="0.04" site="imu"/>
    <framepos name="cheat_trunk_position_world" objname="trunk" objtype="body"/>
    <velocimeter name="cheat_trunk_lin_vel_trunk" site="trunk_cheat_site"/>
    <force name="FR_grf" site="FR_grf_sensor"/>
    <force name="FL_grf" site="FL_grf_sensor"/>
    <force name="RR_grf" site="RR_grf_sensor"/>
    <force name="RL_grf" site="RL_grf_sensor"/>
    <framequat name="FR_foot_quat" objname="FR_grf_sensor" objtype="site"/>
    <framequat name="FL_foot_quat" objname="FL_grf_sensor" objtype="site"/>
    <framequat name="RR_foot_quat" objname="RR_grf_sensor" objtype="site"/>
    <framequat name="RL_foot_quat" objname="RL_grf_sensor" objtype="site"/>
  </sensor>
  <keyframe>
    <key name="home" qpos="0 0 0.4 1 0 0 0 0 0.9 -1.6 0 0.9 -1.6 0 0.9 -1.6 0 0.9 -1.6"/>
  </keyframe>
</mujoco>
